Workbook

Sheet Swimmer_Calcs
A1: Swimmer Recruiting Calculator (Template)
A3: Conference (type exactly):
A4: Optional: Team Tier (1-4):
A5: Optional: School (type exactly):
A6: Enter events you swim + your best time (SCY). The sheet estimates conference place + points using last conference anchors (1st/8th/16th). Points are confidence-weighted near the scoring bubble.
A8: Event | B8: Swimmer Time | C8: Swimmer_sec | D8: 1st_sec | E8: 8th_sec | F8: 16th_sec | G8: Sec_per_place | H8: EstPlace | I8: ExpPoints | J8: Confidence | K8: AdjPoints
C9: =IF(B9="","",IF(ISNUMBER(SEARCH(":",B9)),60*VALUE(LEFT(B9,FIND(":",B9)-1))+VALUE(MID(B9,FIND(":",B9)+1,99)),VALUE(B9))) | D9: =IFERROR(VLOOKUP($B$3&"|"&A9,Sheet1!$K$2:$O$128,2,FALSE),"") | E9: =IFERROR(VLOOKUP($B$3&"|"&A9,Sheet1!$K$2:$O$128,3,FALSE),"") | F9: =IFERROR(VLOOKUP($B$3&"|"&A9,Sheet1!$K$2:$O$128,4,FALSE),"") | G9: =IFERROR(VLOOKUP($B$3&"|"&A9,Sheet1!$K$2:$O$128,5,FALSE),"") | H9: =IF(OR(C9="",D9="",E9="",F9="",G9=""),"",IF(C9<=D9,1,IF(C9<=E9,1+(C9-D9)/(E9-D9)*7,IF(C9<=F9,8+(C9-E9)/(F9-E9)*8,16+(C9-F9)/G9)))) | I9: =IF(H9="","",MAX(0,MIN(20,21-H9))) | J9: =IF(H9="","",IF(H9<=12,1,IF(H9<=14,0.85,IF(H9<=16,0.65,0)))) | K9: =IF(I9="","",I9*J9)
C10: =IF(B10="","",IF(ISNUMBER(SEARCH(":",B10)),60*VALUE(LEFT(B10,FIND(":",B10)-1))+VALUE(MID(B10,FIND(":",B10)+1,99)),VALUE(B10))) | D10: =IFERROR(VLOOKUP($B$3&"|"&A10,Sheet1!$K$2:$O$128,2,FALSE),"") | E10: =IFERROR(VLOOKUP($B$3&"|"&A10,Sheet1!$K$2:$O$128,3,FALSE),"") | F10: =IFERROR(VLOOKUP($B$3&"|"&A10,Sheet1!$K$2:$O$128,4,FALSE),"") | G10: =IFERROR(VLOOKUP($B$3&"|"&A10,Sheet1!$K$2:$O$128,5,FALSE),"") | H10: =IF(OR(C10="",D10="",E10="",F10="",G10=""),"",IF(C10<=D10,1,IF(C10<=E10,1+(C10-D10)/(E10-D10)*7,IF(C10<=F10,8+(C10-E10)/(F10-E10)*8,16+(C10-F10)/G10)))) | I10: =IF(H10="","",MAX(0,MIN(20,21-H10))) | J10: =IF(H10="","",IF(H10<=12,1,IF(H10<=14,0.85,IF(H10<=16,0.65,0)))) | K10: =IF(I10="","",I10*J10)
C11: =IF(B11="","",IF(ISNUMBER(SEARCH(":",B11)),60*VALUE(LEFT(B11,FIND(":",B11)-1))+VALUE(MID(B11,FIND(":",B11)+1,99)),VALUE(B11))) | D11: =IFERROR(VLOOKUP($B$3&"|"&A11,Sheet1!$K$2:$O$128,2,FALSE),"") | E11: =IFERROR(VLOOKUP($B$3&"|"&A11,Sheet1!$K$2:$O$128,3,FALSE),"") | F11: =IFERROR(VLOOKUP($B$3&"|"&A11,Sheet1!$K$2:$O$128,4,FALSE),"") | G11: =IFERROR(VLOOKUP($B$3&"|"&A11,Sheet1!$K$2:$O$128,5,FALSE),"") | H11: =IF(OR(C11="",D11="",E11="",F11="",G11=""),"",IF(C11<=D11,1,IF(C11<=E11,1+(C11-D11)/(E11-D11)*7,IF(C11<=F11,8+(C11-E11)/(F11-E11)*8,16+(C11-F11)/G11)))) | I11: =IF(H11="","",MAX(0,MIN(20,21-H11))) | J11: =IF(H11="","",IF(H11<=12,1,IF(H11<=14,0.85,IF(H11<=16,0.65,0)))) | K11: =IF(I11="","",I11*J11)
C12: =IF(B12="","",IF(ISNUMBER(SEARCH(":",B12)),60*VALUE(LEFT(B12,FIND(":",B12)-1))+VALUE(MID(B12,FIND(":",B12)+1,99)),VALUE(B12))) | D12: =IFERROR(VLOOKUP($B$3&"|"&A12,Sheet1!$K$2:$O$128,2,FALSE),"") | E12: =IFERROR(VLOOKUP($B$3&"|"&A12,Sheet1!$K$2:$O$128,3,FALSE),"") | F12: =IFERROR(VLOOKUP($B$3&"|"&A12,Sheet1!$K$2:$O$128,4,FALSE),"") | G12: =IFERROR(VLOOKUP($B$3&"|"&A12,Sheet1!$K$2:$O$128,5,FALSE),"") | H12: =IF(OR(C12="",D12="",E12="",F12="",G12=""),"",IF(C12<=D12,1,IF(C12<=E12,1+(C12-D12)/(E12-D12)*7,IF(C12<=F12,8+(C12-E12)/(F12-E12)*8,16+(C12-F12)/G12)))) | I12: =IF(H12="","",MAX(0,MIN(20,21-H12))) | J12: =IF(H12="","",IF(H12<=12,1,IF(H12<=14,0.85,IF(H12<=16,0.65,0)))) | K12: =IF(I12="","",I12*J12)
C13: =IF(B13="","",IF(ISNUMBER(SEARCH(":",B13)),60*VALUE(LEFT(B13,FIND(":",B13)-1))+VALUE(MID(B13,FIND(":",B13)+1,99)),VALUE(B13))) | D13: =IFERROR(VLOOKUP($B$3&"|"&A13,Sheet1!$K$2:$O$128,2,FALSE),"") | E13: =IFERROR(VLOOKUP($B$3&"|"&A13,Sheet1!$K$2:$O$128,3,FALSE),"") | F13: =IFERROR(VLOOKUP($B$3&"|"&A13,Sheet1!$K$2:$O$128,4,FALSE),"") | G13: =IFERROR(VLOOKUP($B$3&"|"&A13,Sheet1!$K$2:$O$128,5,FALSE),"") | H13: =IF(OR(C13="",D13="",E13="",F13="",G13=""),"",IF(C13<=D13,1,IF(C13<=E13,1+(C13-D13)/(E13-D13)*7,IF(C13<=F13,8+(C13-E13)/(F13-E13)*8,16+(C13-F13)/G13)))) | I13: =IF(H13="","",MAX(0,MIN(20,21-H13))) | J13: =IF(H13="","",IF(H13<=12,1,IF(H13<=14,0.85,IF(H13<=16,0.65,0)))) | K13: =IF(I13="","",I13*J13)
C14: =IF(B14="","",IF(ISNUMBER(SEARCH(":",B14)),60*VALUE(LEFT(B14,FIND(":",B14)-1))+VALUE(MID(B14,FIND(":",B14)+1,99)),VALUE(B14))) | D14: =IFERROR(VLOOKUP($B$3&"|"&A14,Sheet1!$K$2:$O$128,2,FALSE),"") | E14: =IFERROR(VLOOKUP($B$3&"|"&A14,Sheet1!$K$2:$O$128,3,FALSE),"") | F14: =IFERROR(VLOOKUP($B$3&"|"&A14,Sheet1!$K$2:$O$128,4,FALSE),"") | G14: =IFERROR(VLOOKUP($B$3&"|"&A14,Sheet1!$K$2:$O$128,5,FALSE),"") | H14: =IF(OR(C14="",D14="",E14="",F14="",G14=""),"",IF(C14<=D14,1,IF(C14<=E14,1+(C14-D14)/(E14-D14)*7,IF(C14<=F14,8+(C14-E14)/(F14-E14)*8,16+(C14-F14)/G14)))) | I14: =IF(H14="","",MAX(0,MIN(20,21-H14))) | J14: =IF(H14="","",IF(H14<=12,1,IF(H14<=14,0.85,IF(H14<=16,0.65,0)))) | K14: =IF(I14="","",I14*J14)
C15: =IF(B15="","",IF(ISNUMBER(SEARCH(":",B15)),60*VALUE(LEFT(B15,FIND(":",B15)-1))+VALUE(MID(B15,FIND(":",B15)+1,99)),VALUE(B15))) | D15: =IFERROR(VLOOKUP($B$3&"|"&A15,Sheet1!$K$2:$O$128,2,FALSE),"") | E15: =IFERROR(VLOOKUP($B$3&"|"&A15,Sheet1!$K$2:$O$128,3,FALSE),"") | F15: =IFERROR(VLOOKUP($B$3&"|"&A15,Sheet1!$K$2:$O$128,4,FALSE),"") | G15: =IFERROR(VLOOKUP($B$3&"|"&A15,Sheet1!$K$2:$O$128,5,FALSE),"") | H15: =IF(OR(C15="",D15="",E15="",F15="",G15=""),"",IF(C15<=D15,1,IF(C15<=E15,1+(C15-D15)/(E15-D15)*7,IF(C15<=F15,8+(C15-E15)/(F15-E15)*8,16+(C15-F15)/G15)))) | I15: =IF(H15="","",MAX(0,MIN(20,21-H15))) | J15: =IF(H15="","",IF(H15<=12,1,IF(H15<=14,0.85,IF(H15<=16,0.65,0)))) | K15: =IF(I15="","",I15*J15)
C16: =IF(B16="","",IF(ISNUMBER(SEARCH(":",B16)),60*VALUE(LEFT(B16,FIND(":",B16)-1))+VALUE(MID(B16,FIND(":",B16)+1,99)),VALUE(B16))) | D16: =IFERROR(VLOOKUP($B$3&"|"&A16,Sheet1!$K$2:$O$128,2,FALSE),"") | E16: =IFERROR(VLOOKUP($B$3&"|"&A16,Sheet1!$K$2:$O$128,3,FALSE),"") | F16: =IFERROR(VLOOKUP($B$3&"|"&A16,Sheet1!$K$2:$O$128,4,FALSE),"") | G16: =IFERROR(VLOOKUP($B$3&"|"&A16,Sheet1!$K$2:$O$128,5,FALSE),"") | H16: =IF(OR(C16="",D16="",E16="",F16="",G16=""),"",IF(C16<=D16,1,IF(C16<=E16,1+(C16-D16)/(E16-D16)*7,IF(C16<=F16,8+(C16-E16)/(F16-E16)*8,16+(C16-F16)/G16)))) | I16: =IF(H16="","",MAX(0,MIN(20,21-H16))) | J16: =IF(H16="","",IF(H16<=12,1,IF(H16<=14,0.85,IF(H16<=16,0.65,0)))) | K16: =IF(I16="","",I16*J16)
C17: =IF(B17="","",IF(ISNUMBER(SEARCH(":",B17)),60*VALUE(LEFT(B17,FIND(":",B17)-1))+VALUE(MID(B17,FIND(":",B17)+1,99)),VALUE(B17))) | D17: =IFERROR(VLOOKUP($B$3&"|"&A17,Sheet1!$K$2:$O$128,2,FALSE),"") | E17: =IFERROR(VLOOKUP($B$3&"|"&A17,Sheet1!$K$2:$O$128,3,FALSE),"") | F17: =IFERROR(VLOOKUP($B$3&"|"&A17,Sheet1!$K$2:$O$128,4,FALSE),"") | G17: =IFERROR(VLOOKUP($B$3&"|"&A17,Sheet1!$K$2:$O$128,5,FALSE),"") | H17: =IF(OR(C17="",D17="",E17="",F17="",G17=""),"",IF(C17<=D17,1,IF(C17<=E17,1+(C17-D17)/(E17-D17)*7,IF(C17<=F17,8+(C17-E17)/(F17-E17)*8,16+(C17-F17)/G17)))) | I17: =IF(H17="","",MAX(0,MIN(20,21-H17))) | J17: =IF(H17="","",IF(H17<=12,1,IF(H17<=14,0.85,IF(H17<=16,0.65,0)))) | K17: =IF(I17="","",I17*J17)
C18: =IF(B18="","",IF(ISNUMBER(SEARCH(":",B18)),60*VALUE(LEFT(B18,FIND(":",B18)-1))+VALUE(MID(B18,FIND(":",B18)+1,99)),VALUE(B18))) | D18: =IFERROR(VLOOKUP($B$3&"|"&A18,Sheet1!$K$2:$O$128,2,FALSE),"") | E18: =IFERROR(VLOOKUP($B$3&"|"&A18,Sheet1!$K$2:$O$128,3,FALSE),"") | F18: =IFERROR(VLOOKUP($B$3&"|"&A18,Sheet1!$K$2:$O$128,4,FALSE),"") | G18: =IFERROR(VLOOKUP($B$3&"|"&A18,Sheet1!$K$2:$O$128,5,FALSE),"") | H18: =IF(OR(C18="",D18="",E18="",F18="",G18=""),"",IF(C18<=D18,1,IF(C18<=E18,1+(C18-D18)/(E18-D18)*7,IF(C18<=F18,8+(C18-E18)/(F18-E18)*8,16+(C18-F18)/G18)))) | I18: =IF(H18="","",MAX(0,MIN(20,21-H18))) | J18: =IF(H18="","",IF(H18<=12,1,IF(H18<=14,0.85,IF(H18<=16,0.65,0)))) | K18: =IF(I18="","",I18*J18)
C19: =IF(B19="","",IF(ISNUMBER(SEARCH(":",B19)),60*VALUE(LEFT(B19,FIND(":",B19)-1))+VALUE(MID(B19,FIND(":",B19)+1,99)),VALUE(B19))) | D19: =IFERROR(VLOOKUP($B$3&"|"&A19,Sheet1!$K$2:$O$128,2,FALSE),"") | E19: =IFERROR(VLOOKUP($B$3&"|"&A19,Sheet1!$K$2:$O$128,3,FALSE),"") | F19: =IFERROR(VLOOKUP($B$3&"|"&A19,Sheet1!$K$2:$O$128,4,FALSE),"") | G19: =IFERROR(VLOOKUP($B$3&"|"&A19,Sheet1!$K$2:$O$128,5,FALSE),"") | H19: =IF(OR(C19="",D19="",E19="",F19="",G19=""),"",IF(C19<=D19,1,IF(C19<=E19,1+(C19-D19)/(E19-D19)*7,IF(C19<=F19,8+(C19-E19)/(F19-E19)*8,16+(C19-F19)/G19)))) | I19: =IF(H19="","",MAX(0,MIN(20,21-H19))) | J19: =IF(H19="","",IF(H19<=12,1,IF(H19<=14,0.85,IF(H19<=16,0.65,0)))) | K19: =IF(I19="","",I19*J19)
C20: =IF(B20="","",IF(ISNUMBER(SEARCH(":",B20)),60*VALUE(LEFT(B20,FIND(":",B20)-1))+VALUE(MID(B20,FIND(":",B20)+1,99)),VALUE(B20))) | D20: =IFERROR(VLOOKUP($B$3&"|"&A20,Sheet1!$K$2:$O$128,2,FALSE),"") | E20: =IFERROR(VLOOKUP($B$3&"|"&A20,Sheet1!$K$2:$O$128,3,FALSE),"") | F20: =IFERROR(VLOOKUP($B$3&"|"&A20,Sheet1!$K$2:$O$128,4,FALSE),"") | G20: =IFERROR(VLOOKUP($B$3&"|"&A20,Sheet1!$K$2:$O$128,5,FALSE),"") | H20: =IF(OR(C20="",D20="",E20="",F20="",G20=""),"",IF(C20<=D20,1,IF(C20<=E20,1+(C20-D20)/(E20-D20)*7,IF(C20<=F20,8+(C20-E20)/(F20-E20)*8,16+(C20-F20)/G20)))) | I20: =IF(H20="","",MAX(0,MIN(20,21-H20))) | J20: =IF(H20="","",IF(H20<=12,1,IF(H20<=14,0.85,IF(H20<=16,0.65,0)))) | K20: =IF(I20="","",I20*J20)
H23: Top-3 Adjusted Points | I23: =SUM(IFERROR(LARGE(K9:K20,1),0),IFERROR(LARGE(K9:K20,2),0),IFERROR(LARGE(K9:K20,3),0))
H24: Conference Recruitability | I24: =IF(I23<1,"Moonshot",IF(I23<4,"Reach",IF(I23<10,"Recruitable",IF(I23<18,"Priority Recruit",IF(I23<35,"Likely Commit",IF(I23<50,"Conference Star","High-Point Contender"))))))))
H25: At This Team (Tier Adjusted) | I25: =IF(AND($B$4="",$B$5=""),I24,IF(I26<1,"Moonshot",IF(I26<4,"Reach",IF(I26<10,"Recruitable",IF(I26<18,"Priority Recruit",IF(I26<35,"Likely Commit",IF(I26<50,"Conference Star","High-Point Contender"))))))))
H26: Program-Adjusted Points | I26: =I23*IF($B$5<>"",IFERROR(VLOOKUP($B$3&"|"&$B$5,Team_Tiers!$G$2:$L$200,6,FALSE),1),IF($B$4="",1,IF($B$4=1,IF(IFERROR(VLOOKUP($B$3,Team_Tiers!$N$2:$O$50,2,FALSE),0)>2.3,0.70,IF(IFERROR(VLOOKUP($B$3,Team_Tiers!$N$2:$O$50,2,FALSE),0)>=1.8,0.78,0.85)),IF($B$4=2,1,IF($B$4=3,1.1,IF($B$4=4,1.2,1))))))

Sheet Sheet1
A1: Conference | B1: Event | C1: 1st | D1: 8th | E1: 16th | F1: 1st_sec | G1: 8th_sec | H1: 16th_sec | I1: Gap_8_16 | J1: Sec_per_place | K1: Key | L1: LU_1st_sec | M1: LU_8th_sec | N1: LU_16th_sec | O1: LU_Sec_per_place
A2: Liberty League | B2: 50 Free | C2: 20.41 | D2: 21.17 | E2: 22.03 | F2: 20.41 | G2: 21.17 | H2: 22.03 | I2: 0.86 | J2: 0.1075 | K2: Liberty League|50 Free | L2: 20.41 | M2: 21.17 | N2: 22.03 | O2: 0.1075
A3: Liberty League | B3: 100 Free | C3: 44.88 | D3: 46.59 | E3: 48.05 | F3: 44.88 | G3: 46.59 | H3: 48.05 | I3: 1.46 | J3: 0.1825 | K3: Liberty League|100 Free | L3: 44.88 | M3: 46.59 | N3: 48.05 | O3: 0.1825
A4: Liberty League | B4: 200 Free | C4: 1:39.33 | D4: 1:42.62 | E4: 1:45.27 | F4: 99.33 | G4: 102.62 | H4: 105.27 | I4: 2.65 | J4: 0.33125 | K4: Liberty League|200 Free | L4: 99.33 | M4: 102.62 | N4: 105.27 | O4: 0.33125
A5: Liberty League | B5: 500 Free | C5: 4:31.98 | D5: 4:44.56 | E5: 5:03.42 | F5: 271.98 | G5: 284.56 | H5: 303.42 | I5: 18.86 | J5: 2.3575 | K5: Liberty League|500 Free | L5: 271.98 | M5: 284.56 | N5: 303.42 | O5: 2.3575
A6: Liberty League | B6: 1650 Free | C6: 15:50.52 | D6: 16:45.39 | E6: 17:28.80 | F6: 950.52 | G6: 1005.39 | H6: 1048.8 | I6: 43.41 | J6: 5.42625 | K6: Liberty League|1650 Free | L6: 950.52 | M6: 1005.39 | N6: 1048.8 | O6: 5.42625
A7: Liberty League | B7: 100 Back | C7: 48.95 | D7: 51.27 | E7: 53.98 | F7: 48.95 | G7: 51.27 | H7: 53.98 | I7: 2.71 | J7: 0.33875 | K7: Liberty League|100 Back | L7: 48.95 | M7: 51.27 | N7: 53.98 | O7: 0.33875
A8: Liberty League | B8: 200 Back | C8: 1:47.11 | D8: 1:53.78 | E8: 1:59.62 | F8: 107.11 | G8: 113.78 | H8: 119.62 | I8: 5.84 | J8: 0.73 | K8: Liberty League|200 Back | L8: 107.11 | M8: 113.78 | N8: 119.62 | O8: 0.73
A9: Liberty League | B9: 100 Breast | C9: 55.49 | D9: 57.88 | E9: 1:01.68 | F9: 55.49 | G9: 57.88 | H9: 61.68 | I9: 3.8 | J9: 0.475 | K9: Liberty League|100 Breast | L9: 55.49 | M9: 57.88 | N9: 61.68 | O9: 0.475
A10: Liberty League | B10: 200 Breast | C10: 2:01.44 | D10: 2:08.33 | E10: 2:15.94 | F10: 121.44 | G10: 128.33 | H10: 135.94 | I10: 7.61 | J10: 0.95125 | K10: Liberty League|200 Breast | L10: 121.44 | M10: 128.33 | N10: 135.94 | O10: 0.95125
A11: Liberty League | B11: 100 Fly | C11: 48.57 | D11: 50.94 | E11: 53.41 | F11: 48.57 | G11: 50.94 | H11: 53.41 | I11: 2.47 | J11: 0.30875 | K11: Liberty League|100 Fly | L11: 48.57 | M11: 50.94 | N11: 53.41 | O11: 0.30875
A12: Liberty League | B12: 200 Fly | C12: 1:48.52 | D12: 1:54.66 | E12: 2:01.33 | F12: 108.52 | G12: 114.66 | H12: 121.33 | I12: 6.67 | J12: 0.83375 | K12: Liberty League|200 Fly | L12: 108.52 | M12: 114.66 | N12: 121.33 | O12: 0.83375
A13: Liberty League | B13: 200 IM | C13: 1:54.03 | D13: 1:56.30 | E13: 1:58.29 | F13: 114.03 | G13: 116.3 | H13: 118.29 | I13: 1.99 | J13: 0.24875 | K13: Liberty League|200 IM | L13: 114.03 | M13: 116.3 | N13: 118.29 | O13: 0.24875
... A128: UAA | B128: 50 Breast (Relay Split) | C128: 23.92 | D128: 25.54 | E128: 26.88 | F128: 23.92 | G128: 25.54 | H128: 26.88 | I128: 1.34 | J128: 0.1675 | K128: UAA|50 Breast (Relay Split) | L128: 23.92 | M128: 25.54 | N128: 26.88 | O128: 0.1675

Sheet Team_Tiers
A1: Conference | B1: Finish | C1: Team | D1: MenPoints | E1: Tier | F1: SourcePage | G1: Key | H1: ChampionPoints | I1: MedianPoints | J1: DominanceIndex | K1: IsChampion | L1: PSF | M1: PowerClass | N1: Conference | O1: DominanceIndex | P1: ChampionPoints | Q1: MedianPoints | R1: ChampionMeetShare | S1: ChampionPowerClass | T1: ChampionRatio | U1: MeetTotalPoints | V1: MeetShare
A2: Centennial | B2: 1 | C2: Johns Hopkins University | D2: 940.5 | E2: Tier 1 | F2: 108 | G2: Centennial|Johns Hopkins University | H2: 940.5 | I2: 294 | J2: 3.1989796 | K2: 1 | L2: 0.7 | M2: Super Powerhouse | N2: Centennial | O2: 3.1989796 | P2: 940.5 | Q2: 294 | R2: 0.2677199 | S2: Super Powerhouse | T2: 1 | U2: 3513 | V2: 0.2677199
A3: Centennial | B3: 2 | C3: Gettysburg College | D3: 726 | E3: Tier 2 | F3: 108 | G3: Centennial|Gettysburg College | H3: 940.5 | I3: 294 | J3: 3.1989796 | K3: 0 | L3: 1 | N3: Liberty League | O3: 2.6150342 | P3: 1722 | Q3: 658.5 | R3: 0.21367415 | S3: Super Powerhouse | T3: 0.77192982 | U3: 3513 | V3: 0.20666097
A4: Centennial | B4: 3 | C4: Swarthmore College | D4: 675 | E4: Tier 2 | F4: 108 | G4: Centennial|Swarthmore College | H4: 940.5 | I4: 294 | J4: 3.1989796 | K4: 0 | L4: 1 | N4: NCAC | O4: 1.9014563 | P4: 1958.5 | Q4: 1030 | R4: 0.21251085 | S4: Powerhouse | T4: 0.71770335 | U4: 3513 | V4: 0.19214347
A5: Centennial | B5: 4 | C5: Dickinson College | D5: 311 | E5: Tier 4 | F5: 108 | G5: Centennial|Dickinson College | H5: 940.5 | I5: 294 | J5: 3.1989796 | K5: 0 | L5: 1.2 | N5: NESCAC | O5: 1.9975016 | P5: 1599 | Q5: 800.5 | R5: 0.15894632 | S5: Powerhouse | T5: 0.33067517 | U5: 3513 | V5: 0.088528323
A6: Centennial | B6: 5 | C6: Franklin & Marshall College | D6: 277 | E6: Tier 4 | F6: 108 | G6: Centennial|Franklin & Marshall College | H6: 940.5 | I6: 294 | J6: 3.1989796 | K6: 0 | L6: 1.2 | N6: NEWMAC | O6: 2.140896 | P6: 1481.5 | Q6: 692 | R6: 0.28337796 | S6: Super Powerhouse | T6: 0.29452419 | U6: 3513 | V6: 0.078849986
A7: Centennial | B7: 6 | C7: Ursinus College | D7: 229 | E7: Tier 4 | F7: 108 | G7: Centennial|Ursinus College | H7: 940.5 | I7: 294 | J7: 3.1989796 | K7: 0 | L7: 1.2 | N7: NWC | O7: 2.5735294 | P7: 875 | Q7: 340 | R7: 0.27386541 | S7: Super Powerhouse | T7: 0.24348751 | U7: 3513 | V7: 0.06518645
A8: Centennial | B8: 7 | C8: Washington College | D8: 219.5 | E8: Tier 4 | F8: 108 | G8: Centennial|Washington College | H8: 940.5 | I8: 294 | J8: 3.1989796 | K8: 0 | L8: 1.2 | N8: SCIAC | O8: 2.6156028 | P8: 922 | Q8: 352.5 | R8: 0.23466531 | S8: Super Powerhouse | T8: 0.2333865 | U8: 3513 | V8: 0.062482209
A9: Centennial | B9: 8 | C9: McDaniel College Swim Team | D9: 135 | E9: Tier 4 | F9: 108 | G9: Centennial|McDaniel College Swim Team | H9: 940.5 | I9: 294 | J9: 3.1989796 | K9: 0 | L9: 1.2 | N9: UAA | O9: 1.6577641 | P9: 1753.5 | Q9: 1057.75 | R9: 0.20525576 | S9: Powerhouse | T9: 0.14354067 | U9: 3513 | V9: 0.038428693
A10: Liberty League | B10: 1 | C10: Ithaca College | D10: 1722 | E10: Tier 1 | F10: 113 | G10: Liberty League|Ithaca College | H10: 1722 | I10: 658.5 | J10: 2.6150342 | K10: 1 | L10: 0.7 | M10: Super Powerhouse | N10: MIAC | O10: 1.8658835 | P10: 953 | Q10: 510.75 | R10: 0.29688474 | S10: Super Powerhouse | T10: 1 | U10: 8059 | V10: 0.21367415
A11: Liberty League | B11: 2 | C11: Rochester Institute of Technol | D11: 1625.5 | E11: Tier 1 | F11: 113 | G11: Liberty League|Rochester Institute of Technol | H11: 1722 | I11: 658.5 | J11: 2.6150342 | K11: 0 | L11: 0.78 | M11: Powerhouse | T11: 0.94396051 | U11: 8059 | V11: 0.20169996
A12: Liberty League | B12: 3 | C12: Rensselaer Polytechnic Institu | D12: 1085 | E12: Tier 2 | F12: 113 | G12: Liberty League|Rensselaer Polytechnic Institu | H12: 1722 | I12: 658.5 | J12: 2.6150342 | K12: 0 | L12: 1 | T12: 0.6300813 | U12: 8059 | V12: 0.13463209
A13: Liberty League | B13: 4 | C13: Clarkson University | D13: 1028.5 | E13: Tier 3 | F13: 113 | G13: Liberty League|Clarkson University | H13: 1722 | I13: 658.5 | J13: 2.6150342 | K13: 0 | L13: 1.1 | T13: 0.59727062 | U13: 8059 | V13: 0.12762129
A14: Liberty League | B14: 5 | C14: Union College (New York) | D14: 686.5 | E14: Tier 3 | F14: 113 | G14: Liberty League|Union College (New York) | H14: 1722 | I14: 658.5 | J14: 2.6150342 | K14: 0 | L14: 1.1 | T14: 0.39866434 | U14: 8059 | V14: 0.085184266
A15: Liberty League | B15: 6 | C15: Skidmore College | D15: 630.5 | E15: Tier 3 | F15: 113 | G15: Liberty League|Skidmore College | H15: 1722 | I15: 658.5 | J15: 2.6150342 | K15: 0 | L15: 1.1 | T15: 0.36614402 | U15: 8059 | V15: 0.078235513
A16: Liberty League | B16: 7 | C16: Vassar College | D16: 522 | E16: Tier 4 | F16: 113 | G16: Liberty League|Vassar College | H16: 1722 | I16: 658.5 | J16: 2.6150342 | K16: 0 | L16: 1.2 | T16: 0.30313589 | U16: 8059 | V16: 0.064772304
A17: Liberty League | B17: 8 | C17: St. Lawrence University | D17: 325 | E17: Tier 4 | F17: 113 | G17: Liberty League|St. Lawrence University | H17: 1722 | I17: 658.5 | J17: 2.6150342 | K17: 0 | L17: 1.2 | T17: 0.18873403 | U17: 8059 | V17: 0.040327584
A18: Liberty League | B18: 9 | C18: Hobart and William Smith | D18: 272 | E18: Tier 4 | F18: 113 | G18: Liberty League|Hobart and William Smith | H18: 1722 | I18: 658.5 | J18: 2.6150342 | K18: 0 | L18: 1.2 | T18: 0.15795587 | U18: 8059 | V18: 0.033751086
A19: Liberty League | B19: 10 | C19: Bard College | D19: 162 | E19: Tier 4 | F19: 113 | G19: Liberty League|Bard College | H19: 1722 | I19: 658.5 | J19: 2.6150342 | K19: 0 | L19: 1.2 | T19: 0.094076655 | U19: 8059 | V19: 0.02010175
A20: NCAC | B20: 1 | C20: Denison University | D20: 1958.5 | E20: Tier 1 | F20: 127 | G20: NCAC|Denison University | H20: 1958.5 | I20: 1030 | J20: 1.9014563 | K20: 1 | L20: 0.78 | M20: Powerhouse | T20: 1 | U20: 9216 | V20: 0.21251085
A21: NCAC | B21: 2 | C21: Kenyon College | D21: 1741.5 | E21: Tier 1 | F21: 127 | G21: NCAC|Kenyon College | H21: 1958.5 | I21: 1030 | J21: 1.9014563 | K21: 0 | L21: 0.78 | M21: Powerhouse | T21: 0.88920092 | U21: 9216 | V21: 0.18896484
A22: NCAC | B22: 3 | C22: John Carroll University | D22: 1192.5 | E22: Tier 2 | F22: 127 | G22: NCAC|John Carroll University | H22: 1958.5 | I22: 1030 | J22: 1.9014563 | K22: 0 | L22: 1 | T22: 0.60888435 | U22: 9216 | V22: 0.12939453
A23: NCAC | B23: 4 | C23: DePauw University | D23: 1095 | E23: Tier 3 | F23: 127 | G23: NCAC|DePauw University | H23: 1958.5 | I23: 1030 | J23: 1.9014563 | K23: 0 | L23: 1.1 | T23: 0.55910135 | U23: 9216 | V23: 0.1188151
A24: NCAC | B24: 5 | C24: Wabash College | D24: 1030 | E24: Tier 3 | F24: 127 | G24: NCAC|Wabash College | H24: 1958.5 | I24: 1030 | J24: 1.9014563 | K24: 0 | L24: 1.1 | T24: 0.52591269 | U24: 9216 | V24: 0.11176215
A25: NCAC | B25: 6 | C25: College of Wooster | D25: 789.5 | E25: Tier 3 | F25: 127 | G25: NCAC|College of Wooster | H25: 1958.5 | I25: 1030 | J25: 1.9014563 | K25: 0 | L25: 1.1 | T25: 0.40311463 | U25: 9216 | V25: 0.085666233
A26: NCAC | B26: 7 | C26: Oberlin College | D26: 786 | E26: Tier 3 | F26: 127 | G26: NCAC|Oberlin College | H26: 1958.5 | I26: 1030 | J26: 1.9014563 | K26: 0 | L26: 1.1 | T26: 0.40132755 | U26: 9216 | V26: 0.085286458
A27: NCAC | B27: 8 | C27: Ohio Wesleyan University | D27: 450 | E27: Tier 4 | F27: 127 | G27: NCAC|Ohio Wesleyan University | H27: 1958.5 | I27: 1030 | J27: 1.9014563 | K27: 0 | L27: 1.2 | T27: 0.22976768 | U27: 9216 | V27: 0.048828125
A28: NCAC | B28: 9 | C28: Wittenberg University | D28: 173 | E28: Tier 4 | F28: 127 | G28: NCAC|Wittenberg University | H28: 1958.5 | I28: 1030 | J28: 1.9014563 | K28: 0 | L28: 1.2 | T28: 0.088332908 | U28: 9216 | V28: 0.018771701
A29: NESCAC | B29: 1 | C29: Williams College | D29: 1599 | E29: Tier 1 | F29: 77 | G29: NESCAC|Williams College | H29: 1599 | I29: 800.5 | J29: 1.9975016 | K29: 1 | L29: 0.78 | M29: Powerhouse | T29: 1 | U29: 10060 | V29: 0.15894632
A30: NESCAC | B30: 2 | C30: Tufts University | D30: 1562 | E30: Tier 1 | F30: 77 | G30: NESCAC|Tufts University | H30: 1599 | I30: 800.5 | J30: 1.9975016 | K30: 0 | L30: 0.78 | M30: Powerhouse | T30: 0.97686054 | U30: 10060 | V30: 0.15526839
A31: NESCAC | B31: 3 | C31: Amherst College | D31: 1217 | E31: Tier 2 | F31: 77 | G31: NESCAC|Amherst College | H31: 1599 | I31: 800.5 | J31: 1.9975016 | K31: 0 | L31: 1 | T31: 0.76110069 | U31: 10060 | V31: 0.12097416
A32: NESCAC | B32: 4 | C32: Connecticut College | D32: 1077 | E32: Tier 2 | F32: 77 | G32: NESCAC|Connecticut College | H32: 1599 | I32: 800.5 | J32: 1.9975016 | K32: 0 | L32: 1 | T32: 0.67354597 | U32: 10060 | V32: 0.10705765
A33: NESCAC | B33: 5 | C33: Bates College | D33: 1041.5 | E33: Tier 2 | F33: 77 | G33: NESCAC|Bates College | H33: 1599 | I33: 800.5 | J33: 1.9975016 | K33: 0 | L33: 1 | T33: 0.65134459 | U33: 10060 | V33: 0.10352883
A34: NESCAC | B34: 6 | C34: Hamilton College | D34: 800.5 | E34: Tier 3 | F34: 77 | G34: NESCAC|Hamilton College | H34: 1599 | I34: 800.5 | J34: 1.9975016 | K34: 0 | L34: 1.1 | T34: 0.50062539 | U34: 10060 | V34: 0.079572565
A35: NESCAC | B35: 7 | C35: Bowdoin College | D35: 768 | E35: Tier 3 | F35: 77 | G35: NESCAC|Bowdoin College | H35: 1599 | I35: 800.5 | J35: 1.9975016 | K35: 0 | L35: 1.1 | T35: 0.48030019 | U35: 10060 | V35: 0.076341948
A36: NESCAC | B36: 8 | C36: Middlebury College | D36: 702 | E36: Tier 3 | F36: 77 | G36: NESCAC|Middlebury College | H36: 1599 | I36: 800.5 | J36: 1.9975016 | K36: 0 | L36: 1.1 | T36: 0.43902439 | U36: 10060 | V36: 0.069781312
A37: NESCAC | B37: 9 | C37: Colby College | D37: 697 | E37: Tier 3 | F37: 77 | G37: NESCAC|Colby College | H37: 1599 | I37: 800.5 | J37: 1.9975016 | K37: 0 | L37: 1.1 | T37: 0.43589744 | U37: 10060 | V37: 0.069284294
A38: NESCAC | B38: 10 | C38: Trinity College | D38: 373 | E38: Tier 4 | F38: 77 | G38: NESCAC|Trinity College | H38: 1599 | I38: 800.5 | J38: 1.9975016 | K38: 0 | L38: 1.2 | T38: 0.23327079 | U38: 10060 | V38: 0.037077535
A39: NESCAC | B39: 11 | C39: Wesleyan University | D39: 223 | E39: Tier 4 | F39: 77 | G39: NESCAC|Wesleyan University | H39: 1599 | I39: 800.5 | J39: 1.9975016 | K39: 0 | L39: 1.2 | T39: 0.13946216 | U39: 10060 | V39: 0.022166998
A40: NEWMAC | B40: 1 | C40: Massachusetts Institute of Tec | D40: 1481.5 | E40: Tier 1 | F40: 91 | G40: NEWMAC|Massachusetts Institute of Tec | H40: 1481.5 | I40: 692 | J40: 2.140896 | K40: 1 | L40: 0.7 | M40: Super Powerhouse | T40: 1 | U40: 5228 | V40: 0.28337796
...
